Workbook
Name Rubriques_Charges: Liste!$A$30:$A$36
Name Rubriques_Produit: Liste!$A$1:$A$9
Name Type: Liste!$C$1:$C$12
Name Rubriques_Charges: [1]Liste!$A$30:$A$36
Name Rubriques_Produit: [1]Liste!$A$1:$A$9
Name Type: [1]Liste!$C$1:$C$12

Sheet Lisez-moi
A1: Compta version 2.0 du 14/11/2021
A2: Concepteur Gilles ETIENNE
A3: Validation Guy DELMAS
A5: Cette feuille de calcul va vous aider à saisir la compta de vos sections.
A6: Vous trouverez 3 onglets essentiels : Bilan, Charges, Produits
A8: Bilan :
A9: Regroupe le bilan de l'année N-1, la prévision de l'année en cours, la saisie de l'année en cours et les prévisions de l'année N+1
A10: Dans cet onglet, seuls le bilan de l'année N-1, la prévision de l'année en cours et les prévisions de l'année N+1 sont à renseigner.
A11: La saisie de l'année en cours se fait par la saisie des opérations de banque dans les onglets Charges et Produits
A12: La section à laquelle vous appartenez doir être mentionnée en cellule C1
A14: Saisir le nom de la section en C1
A16: CHARGES
... A61: Dans le doute sur la rubrique de saisie, l'onglet Rubrique Produits vous aidera à choisir sinon, laissez un message à uso94@orange.fr

Sheet Bilan
A1: SECTION
A2: Charges | J2: Produits
A3: Imputation | B3: Rubrique | C3: Thème | D3: Exercice N-1 | E3: Prévisionnel N | F3: Exercice N | G3: Prévisionnel N+1 | J3: Imputation | K3: Rubrique | L3: Thème | M3: Exercice N-1 | N3: Prévisionnel N | O3: Exercice N | P3: Prévisionnel N+1
A4: 60 | B4: Achats | C4: Achats | D4: =SUM(D5:D11) | E4: =SUM(E5:E11) | F4: =SUM(F5:F11) | G4: =SUM(G5:G11) | J4: 70 | K4: Ventes de produits, marchandises, prestations de services | L4: Ventes de produits, marchandises, prestations de services | M4: =SUM(M5:M11) | N4: =SUM(N5:N11) | O4: =SUM(O5:O11) | P4: =SUM(P5:P11)
C5: Achats d'études et prestations de service | F5: =SUMIF(Charges!J:J,C5,Charges!K:K) | L5: Prestations de service | M5: 0 | O5: =SUMIF(Produits!J:J,L5,Produits!K:K)
C6: Achats alimentaires | F6: =SUMIF(Charges!J:J,C6,Charges!K:K) | L6: Ventes de marchandises (buvette…) | M6: 0 | O6: =SUMIF(Produits!J:J,L6,Produits!K:K)
C7: Achats matériels et équipements sportifs | F7: =SUMIF(Charges!J:J,C7,Charges!K:K) | L7: Ventes produits | M7: 0 | O7: =SUMIF(Produits!J:J,L7,Produits!K:K)
C8: Achats tenues sportives | F8: =SUMIF(Charges!J:J,C8,Charges!K:K) | L8: Vente équipements sportifs | M8: 0 | O8: =SUMIF(Produits!J:J,L8,Produits!K:K)
C9: Electricité, eau, gaz, combustibles | F9: =SUMIF(Charges!J:J,C9,Charges!K:K) | L9: Produits des activités annexes | M9: 0 | O9: =SUMIF(Produits!J:J,L9,Produits!K:K)
C10: Autres achats | F10: =SUMIF(Charges!J:J,C10,Charges!K:K) | L10: Prestations de service pour autres organismes publics | M10: 0 | O10: =SUMIF(Produits!J:J,L10,Produits!K:K)
F11: =SUMIF(Charges!J:J,C11,Charges!K:K) | L11: Sponsors | M11: 0 | O11: =SUMIF(Produits!J:J,L11,Produits!K:K)
A12: 61/62 | B12: Charges externes | C12: Charges | D12: =SUM(D13:D29) | E12: =SUM(E13:E29) | F12: =SUM(F13:F29) | G12: =SUM(G13:G29)
C13: Locations | F13: =SUMIF(Charges!J:J,C13,Charges!K:K)
C14: Achats Petits équipements (mobilier, matériel) | F14: =SUMIF(Charges!J:J,C14,Charges!K:K)
C15: Location Salle | F15: =SUMIF(Charges!J:J,C15,Charges!K:K)
C16: Entretien et travaux | F16: =SUMIF(Charges!J:J,C16,Charges!K:K)
C17: Assurance | F17: =SUMIF(Charges!J:J,C17,Charges!K:K)
C18: Documentation | F18: =SUMIF(Charges!J:J,C18,Charges!K:K)
C19: Fournitures de bureau | F19: =SUMIF(Charges!J:J,C19,Charges!K:K)
C20: Rémunération personnel extérieur, honoraire | F20: =SUMIF(Charges!J:J,C20,Charges!K:K)
C21: Publicité | F21: =SUMIF(Charges!J:J,C21,Charges!K:K)
C22: Cadeaux | F22: =SUMIF(Charges!J:J,C22,Charges!K:K)
C23: Déplacements - Missions Collectif | F23: =SUMIF(Charges!J:J,C23,Charges!K:K)
C24: Déplacements - Missions Bureau | F24: =SUMIF(Charges!J:J,C24,Charges!K:K)
... C29: Frais bancaires | F29: =SUMIF(Charges!J:J,C29,Charges!K:K)
A30: 63 | B30: Impôts, Taxes et versements assimilés | C30: Impôts, Taxes et versements assimilés | D30: =SUM(D31) | E30: =SUM(E31) | F30: =SUM(F31) | G30: =SUM(G31)
C31: Impôts, Taxes et versements assimilés | F31: =SUMIF(Charges!J:J,C31,Charges!K:K)
A32: 64 | B32: Charges de Personnel | C32: Charges de personnel | D32: =SUM(D33:D41) | E32: =SUM(E33:E41) | F32: =SUM(F33:F41) | G32: =SUM(G33:G41) | J32: 74 | K32: Subventions d'exploitation | L32: Subventions d'exploitation | M32: =SUM(M33:M41) | N32: =SUM(N33:N41) | O32: =SUM(O33:O41) | P32: =SUM(P33:P41)
C33: Rémunération du personnel (Salaires) | F33: =SUMIF(Charges!J:J,C33,Charges!K:K) | L33: Etat | M33: 0 | O33: =SUMIF(Produits!J:J,L33,Produits!K:K)
C34: Charges sociales et autres charges de personnel | F34: =SUMIF(Charges!J:J,C34,Charges!K:K) | L34: ANS (Ex CNDS) | M34: 0 | O34: =SUMIF(Produits!J:J,L34,Produits!K:K)
C35: Forfait Accompagnateur | F35: =SUMIF(Charges!J:J,C35,Charges!K:K) | L35: Conseil Régional | M35: 0 | O35: =SUMIF(Produits!J:J,L35,Produits!K:K)
C36: Reversion USO | F36: =SUMIF(Charges!J:J,C36,Charges!K:K) | L36: Conseil Départemental | M36: 0 | O36: =SUMIF(Produits!J:J,L36,Produits!K:K)
C37: Formation personnel | F37: =SUMIF(Charges!J:J,C37,Charges!K:K) | L37: Commune | M37: 0 | O37: =SUMIF(Produits!J:J,L37,Produits!K:K)
C38: Salaires versés par l'USO | F38: =SUMIF(Charges!J:J,C38,Charges!K:K) | L38: USO | M38: 0 | O38: =SUMIF(Produits!J:J,L38,Produits!K:K)
L39: Salaires versés par l'USO | M39: 0 | O39: =SUMIF(Produits!J:J,L39,Produits!K:K)
L40: Subvention Fédération | M40: 0 | O40: =SUMIF(Produits!J:J,L40,Produits!K:K)
L41: Autres (préciser) | M41: 0 | O41: =SUMIF(Produits!J:J,L41,Produits!K:K)
A42: 65 | B42: Autres charges de gestion courante | C42: Autres charges de gestion courante | D42: =SUM(D43:D47) | E42: =SUM(E43:E47) | F42: =SUM(F43:F47) | G42: =SUM(G43:G47) | J42: 75 | K42: Autres produits de gestion courante | L42: Autres produits de gestion courante | M42: =SUM(M43:M47) | N42: =SUM(N43:N47) | O42: =SUM(O43:O47) | P42: =SUM(P43:P47)
C43: Autres charges de gestion courante | F43: =SUMIF(Charges!J:J,C43,Charges!K:K) | L43: Cotisations des adhérents | M43: 0 | O43: =SUMIF(Produits!J:J,L43,Produits!K:K)
C44: Fédération Réaffiliation section | F44: =SUMIF(Charges!J:J,C44,Charges!K:K) | L44: Autres produits | M44: 0 | O44: =SUMIF(Produits!J:J,L44,Produits!K:K)
...

Sheet Charges
A1: Code | B1: N° | C1: N° de pièce Comptable | D1: Descriptif | E1: Date | F1: Type | G1: N° chèque | H1: Tiers | I1: Rubrique | J1: Thème | K1: Montant | L1: Banque
A2: C | B2: 1 | C2: =IF(B2<>" ",CONCATENATE(A2,B2)," ") | D2: Ma première charge | E2: 45954 | F2: Chèque | H2: Mon fournisseur | I2: Charges | J2: Entretien et travaux | K2: 1000 | M2: =OFFSET(Liste!E$7,0,VLOOKUP(I4,Liste!$A$14:$C$22,2,FALSE)-1,VLOOKUP(I4,Liste!$A$14:$C$22,3,FALSE),1)
A3: C | B3: =IF(E3>1/1/2001,B2+1," ") | C3: =IF(B3<>" ",CONCATENATE(A3,B3)," ")
A4: C | B4: =IF(E4>1/1/2001,B3+1," ") | C4: =IF(B4<>" ",CONCATENATE(A4,B4)," ")
A5: C | B5: =IF(E5>1/1/2001,B4+1," ") | C5: =IF(B5<>" ",CONCATENATE(A5,B5)," ")
A6: C | B6: =IF(E6>1/1/2001,B5+1," ") | C6: =IF(B6<>" ",CONCATENATE(A6,B6)," ")
A7: C | B7: =IF(E7>1/1/2001,B6+1," ") | C7: =IF(B7<>" ",CONCATENATE(A7,B7)," ")
A8: C | B8: =IF(E8>1/1/2001,B7+1," ") | C8: =IF(B8<>" ",CONCATENATE(A8,B8)," ")
A9: C | B9: =IF(E9>1/1/2001,B8+1," ") | C9: =IF(B9<>" ",CONCATENATE(A9,B9)," ")
A10: C | B10: =IF(E10>1/1/2001,B9+1," ") | C10: =IF(B10<>" ",CONCATENATE(A10,B10)," ")
A11: C | B11: =IF(E11>1/1/2001,B10+1," ") | C11: =IF(B11<>" ",CONCATENATE(A11,B11)," ")
A12: C | B12: =IF(E12>1/1/2001,B11+1," ") | C12: =IF(B12<>" ",CONCATENATE(A12,B12)," ")
A13: C | B13: =IF(E13>1/1/2001,B12+1," ") | C13: =IF(B13<>" ",CONCATENATE(A13,B13)," ")
A14: C | B14: =IF(E14>1/1/2001,B13+1," ") | C14: =IF(B14<>" ",CONCATENATE(A14,B14)," ")
... A1045: C | B1045: =IF(E1045>1/1/2001,B1044+1," ") | C1045: =IF(B1045<>" ",CONCATENATE(A1045,B1045)," ")

Sheet Rubriques Charges
A1: Section 6. [446] Comptes de charges (Classe 6)
A2: Les charges d'exploitation normale et courante sont enregistrées sous les comptes 60 " Achats ", 61/62 " Autres charges externes ", 63 " Impôts, taxes et versements assimilés ", 64 " Charges de personnel " et 65 " Autres charges de gestion courante ".
A3: Les charges rattachées à la gestion financière figurent sous le compte 66 " Charges financières ".
A4: Les charges relatives à des opérations exceptionnelles sont inscrites sous le compte 67 " Charges exceptionnelles ".
A5: Le compte 68 " Dotations aux amortissements et aux provisions " comporte des subdivisions distinguant les charges calculées d'exploitation, financières ou exceptionnelles.
A6: Le compte 69 " Participation des salariés - Impôts sur les bénéfices et assimilés " enregistre les charges de la participation des salariés aux résultats et les impôts sur les bénéfices.
A7: Les charges de la classe 6 sont enregistrées hors taxes récupérables.
A8: Les comptes 60 à 69 n'enregistrent pas les montants affectés à des investissements ou à des placements qui sont à inscrire directement dans les comptes 20 " Immobilisations incorporelles ", 21 " Immobilisations corporelles ",23 " Immobilisations en cours ", 26 " Participations et créances rattachées à des participations ", 27 " Autres immobilisations financières " et 50 " Valeurs mobilières deplacement ".
A9: A titre dérogatoire, si les entités ne sont pas en mesure de faire de telles distinctions au moment même où elles passent leurs écritures, soit qu'elles ne connaissent pas, alors, le caractère des sommes à enregistrer, soit qu'elles ignorent encore l'affectation qui sera donnée à ces sommes, l'affectation des dépenses à réimputer sera effectuée, en fin d'exercice, en les inscrivant, selon leur affectation et leur nature :
A10: ou au débit d'un compte de bilan par le crédit du compte 72 " Production immobilisée " ou par le crédit des subdivisions du compte 79 " Transferts de charges " ;
A11: ou au débit d'un autre compte de charges par le crédit des subdivisions intéressées du compte79 " Transferts de charges ".
A12: Les différentes charges sont enregistrées aux comptes de la classe 6 même lorsqu'elles sont déjà couvertes par des provisions. Les provisions antérieurement constituées sont annulées par le crédit du compte 78 " Reprises sur amortissements et provisions ".
... A96: Le crédit du compte 699 " Produits - Report en arrière des déficits " enregistre le produit résultant du report en arrière des déficits.

Sheet Produits
A1: Code | B1: N° | C1: N° de pièce Comptable | D1: Descriptif | E1: Date | F1: Type | G1: N° chèque | H1: Tiers | I1: Rubrique | J1: Thème | K1: Montant | L1: Banque
A2: P | B2: 1 | C2: =IF(B2<>" ",CONCATENATE(A2,B2)," ") | D2: Mon 1er produit | E2: 45954 | F2: Dépôt Chèque | I2: Ventes de produits, marchandises, prestations de services | J2: Sponsors | K2: 150
A3: P | B3: =IF(D3>1/1/2001,B2+1," ") | C3: =IF(B3<>" ",CONCATENATE(A3,B3)," ")
A4: P | B4: =IF(D4>1/1/2001,B3+1," ") | C4: =IF(B4<>" ",CONCATENATE(A4,B4)," ")
A5: P | B5: =IF(D5>1/1/2001,B4+1," ") | C5: =IF(B5<>" ",CONCATENATE(A5,B5)," ")
A6: P | B6: =IF(D6>1/1/2001,B5+1," ") | C6: =IF(B6<>" ",CONCATENATE(A6,B6)," ")
A7: P | B7: =IF(D7>1/1/2001,B6+1," ") | C7: =IF(B7<>" ",CONCATENATE(A7,B7)," ")
A8: P | B8: =IF(D8>1/1/2001,B7+1," ") | C8: =IF(B8<>" ",CONCATENATE(A8,B8)," ")
A9: P | B9: =IF(D9>1/1/2001,B8+1," ") | C9: =IF(B9<>" ",CONCATENATE(A9,B9)," ")
A10: P | B10: =IF(D10>1/1/2001,B9+1," ") | C10: =IF(B10<>" ",CONCATENATE(A10,B10)," ")
A11: P | B11: =IF(D11>1/1/2001,B10+1," ") | C11: =IF(B11<>" ",CONCATENATE(A11,B11)," ")
A12: P | B12: =IF(D12>1/1/2001,B11+1," ") | C12: =IF(B12<>" ",CONCATENATE(A12,B12)," ")
A13: P | B13: =IF(D13>1/1/2001,B12+1," ") | C13: =IF(B13<>" ",CONCATENATE(A13,B13)," ")
A14: P | B14: =IF(D14>1/1/2001,B13+1," ") | C14: =IF(B14<>" ",CONCATENATE(A14,B14)," ")
... A1026: P | B1026: =IF(D1026>1/1/2001,B1025+1," ") | C1026: =IF(B1026<>" ",CONCATENATE(A1026,B1026)," ")
C1027: =IF(B1027<>" ",CONCATENATE(A1027,B1027)," ")

Sheet Rubrique Produits
A1: Section 7. [447] Comptes de produits (Classe 7)
A2: Les produits d'exploitation normale et courante sont enregistrés dans les comptes 70 " Ventes de produits fabriqués, prestations de services, marchandises ", 71 " Production stockée (ou déstockage) ",72 " Production immobilisée ", 74 " Subventions d'exploitation " et 75 " Autres produits de gestion courante ".
A3: Les produits liés à la gestion financière sont enregistrés dans le compte 76 " Produits financiers ".
A4: Les produits relatifs à des opérations exceptionnelles sont enregistrés dans le compte 77 " Produits exceptionnels ".
A5: Les reprises sur amortissements et provisions sont enregistrées dans le compte 78 " Reprises sur amortissements et provisions " en distinguant les reprises sur charges calculées d'exploitation, financières ou exceptionnelles.
A6: Les transferts de charges sont enregistrés dans le compte 79 " Transfert de charges ".
A7: Les produits de la classe 7 sont enregistrés hors taxes collectées. Par exception, les entités, qui enregistrent leurs produits TVA comprise, rétablissent a posteriori leur montant hors taxe collectée en débitant globalement, pour chaque période d'imposition, les comptes de la classe 7 concernés par le crédit du compte 4457 " Taxes sur le chiffre d'affaires collectées par l'entreprise ".
A8: Ventes de produits fabriqués, prestations de services, marchandises (comptes 70)
A9: Comme les stocks, les ventes sont classées en fonction d’une nomenclature propre à l’entité dont les modalités d’établissement et la compatibilité avec la nomenclature officielle des biens et services sont identiques à celles déjà énoncées à l’occasion du fonctionnement des comptes de la classe 3 (Stocks et en-cours).
A10: Des subdivisions des comptes de ventes peuvent être ouvertes pour identifier :
A11: les ventes en France et à l'étranger ;
A12: les ventes faites par l'entité à des entités liées ou avec lesquelles elle a un lien de participation ;
... A52: Le compte 79 " Transferts de charges " enregistre les charges d'exploitation, financières et exceptionnelles à transférer soit à un compte de bilan, autre que les comptes d'immobilisations, soit à un autre compte de charges.

Sheet Liste
A1: Achats | C1: Chèque
A2: Charges | C2: Carte Bancaire | D2: =OFFSET(E7,0,VLOOKUP(#REF!,A14:C22,2)-1,VLOOKUP(#REF!,A14:C22,3),1)
A3: Impôts, Taxes et versements assimilés | C3: Espèces
A4: Charges de personnel | C4: Dépôt Chèque
A5: Autres charges de gestion courante | C5: Dépôt Espèces
A6: Charges financières(intérêts, agios, …) | C6: DAB (retrait espèces) | E6: Achats | F6: Charges | G6: Impôts, Taxes et versements assimilés | H6: Charges de personnel | I6: Autres charges de gestion courante | J6: Charges financières(intérêts, agios, …) | K6: Charges exceptionnelles (amendes,…) | L6: Dotations aux amortissements et aux provisions | M6: Impots sur les bénéfices et assimilés
A7: Charges exceptionnelles (amendes,…) | C7: Prélèvement | E7: Achats d'études et prestations de service | F7: Locations | G7: Impôts, Taxes et versements assimilés | H7: Rémunération du personnel (Salaires) | I7: Autres charges de gestion courante | J7: Charges financières(intérêts, agios, …) | K7: Charges exceptionnelles (amendes,…) | L7: Dotations aux amortissements et aux provisions | M7: Impots sur les bénéfices et assimilés
A8: Dotations aux amortissements et aux provisions | C8: TIP | E8: Achats alimentaires | F8: Achats Petits équipements (mobilier, matériel) | H8: Charges sociales et autres charges de personnel | I8: Fédération Réaffiliation section
A9: Impots sur les bénéfices et assimilés | C9: Télépaiement | E9: Achats matériels et équipements sportifs | F9: Location Salle | H9: Forfait Accompagnateur | I9: Fédération Licences
C10: Virement émis | E10: Achats tenues sportives | F10: Entretien et travaux | H10: Reversion USO | I10: Fédération Engagements équipes
C11: Virement reçu | E11: Electricité, eau, gaz, combustibles | F11: Assurance | H11: Formation personnel | I11: Fédération Arbitrage
C12: Autres | E12: Autres achats | F12: Documentation | H12: Salaires versés par l'USO
A13: Rubriques pour colonnes | B13: N° colonne | C13: Nbre de valeurs | F13: Fournitures de bureau
A14: Achats | B14: 1 | C14: 6 | F14: Rémunération personnel extérieur, honoraire
A15: Charges | B15: 2 | C15: 17 | F15: Publicité
A16: Impôts, Taxes et versements assimilés | B16: 3 | C16: 1 | F16: Cadeaux
A17: Charges de personnel | B17: 4 | C17: 6 | F17: Déplacements - Missions Collectif
A18: Autres charges de gestion courante | B18: 5 | C18: 5 | F18: Déplacements - Missions Bureau
A19: Charges financières(intérêts, agios, …) | B19: 6 | C19: 1 | F19: Réceptions Bureau
A20: Charges exceptionnelles (amendes,…) | B20: 7 | C20: 1 | F20: Inscriptions Tournois
A21: Dotations aux amortissements et aux provisions | B21: 8 | C21: 1 | F21: Frais postaux
A22: Impots sur les bénéfices et assimilés | B22: 9 | C22: 1 | F22: Télécom (téléphone/Internet)
F23: Frais bancaires
A29: Rubriques pour colonnes | B29: N° colonne | C29: Nbre de valeurs | E29: Ventes de produits, marchandises, prestations de services | F29: Subventions d'exploitation | G29: Autres produits de gestion courante | H29: Produits financiers | I29: Produits exceptionnels | J29: Reprises sur amortissemenet et provision | K29: Transferts de charges
A30: Ventes de produits, marchandises, prestations de services | B30: 1 | C30: 7 | E30: Prestations de service | F30: Etat | G30: Cotisations des adhérents | H30: Produits financiers | I30: Produits exceptionnels | J30: Reprises sur amortissemenet et provision | K30: Salaires
A31: Subventions d'exploitation | B31: 2 | C31: 10 | E31: Ventes de marchandises (buvette…) | F31: ANS (Ex CNDS) | G31: Autres produits
A32: Autres produits de gestion courante | B32: 3 | C32: 3 | E32: Ventes produits | F32: Conseil Régional | G32: Cotisation des adhérents N+1
A33: Produits financiers | B33: 4 | C33: 1 | E33: Produits des activités annexes | F33: Conseil Départemental
A34: Produits exceptionnels | B34: 5 | C34: 1 | E34: Prestations de service pour autres organismes publics | F34: Commune
A35: Reprises sur amortissemenet et provision | B35: 6 | C35: 1 | E35: Vente équipements sportifs | F35: USO
A36: Transferts de charges | B36: 7 | C36: 1 | E36: Sponsors | F36: Salaires versés par l'USO
F37: Subvention Fédération
F38: Autres (préciser)
